Workbook
Name AAD: BILAN!$I$11
Name AAI: BILAN!$I$16
Name AAP: BILAN!$I$22
Name AAQ: BILAN!$I$23
Name ABK: BILAN!$I$33
Name ABT: BILAN!$I$37
Name ABU: BILAN!$I$38
Name ad: BILAN!$H$11
Name AI: BILAN!$H$16
Name AP: BILAN!$H$22
Name AQ: BILAN!$H$23
Name BK: BILAN!$H$33
Name BT: BILAN!$H$37
Name BU: BILAN!$H$38
Name ECEN: 'Table TFT'!$G$25
Name ECH: 'Table TFT'!$P$26
Name ECHN: 'Table TFT'!$G$26
Name ECN: 'Table TFT'!$P$25
Name EPA: 'Table TFT'!$Q$27
Name EPB: 'Table TFT'!$Q$28
Name EPH: 'Table TFT'!$H$28
Name EPN: 'Table TFT'!$H$27
Name Forme: FormeJuridique[Forme]

Sheet Referentiels
A1: TABLEAU | B1: FR1 | C1: FR2A | G1: FR1 & FR2B | H1: NOTE3B | I1: NOTE13B | K1: FR2C | L1: NOTE4B
A2: CHAMP | B2: ZS | C2: ZX | D2: ZY | E2: ZZ1 | F2: Contrôle de l'Entité | G2: Code nomenclature d'activité | H2: NATURE DU CONTRAT | I2: Nationalité & Pays de résidence | J2: NATURE DES ACTIONS OU PARTS | K2: Unité de mesure de l'activité | L2: Année du dernier exercice filiale
A3: LIBELLES | B3: Oui | C3: 00 | D3: 1 | E3: 01 | F3: Entité sous contrôle public | G3: A0101 | H3: I | I3: Afghanistan | J3: Ordinaires | K3: Chiffre d'affaires HT (CA HT) | L3: N
B4: Non | C4: 01 | D4: 2 | E4: 02 | F4: Entité sous contrôle privé national | G4: A010101 | H4: M | I4: Afrique du Sud | J4: Préférences | K4: Valeur ajoutée (VA) | L4: N-1
C5: 02 | D5: 3 | E5: 03 | F5: Entité sous contrôle privé étranger | G5: A010102 | H5: A | I5: Albanie
C6: 03 | D6: 4 | E6: 04 | G6: A010103 | I6: Algérie
C7: 04 | E7: 05 | G7: A010104 | I7: Allemagne
C8: 05 | E8: 06 | G8: A0102 | I8: Andorre
C9: 06 | E9: 07 | G9: A010201 | I9: Angola
C10: 07 | E10: 08 | G10: A010202 | I10: Anguilla
C11: 08 | E11: 09 | G11: A010203 | I11: Antarctique
C12: 09 | E12: 10 | G12: A010204 | I12: Antigua-et-Barbuda
C13: 10 | E13: 11 | G13: A010205 | I13: Antilles Néerlandaises
C14: 11 | E14: 12 | G14: A010206 | I14: Arabie Saoudite
C15: 12 | E15: 13 | G15: A010207 | I15: Argentine
C16: 13 | E16: 14 | G16: A010208 | I16: Arménie
C17: 14 | E17: 15 | G17: A010209 | I17: Aruba
C18: 15 | E18: 16 | G18: A010210 | I18: Australie
C19: 16 | E19: 20 | G19: A0103 | I19: Autriche
C20: 17 | E20: 21 | G20: A010301 | I20: Azerbaïdjan
C21: 18 | E21: 22 | G21: A010302 | I21: Bahamas
C22: 19 | E22: 23 | G22: A0104 | I22: Bahreïn
E23: 39 | G23: A010401 | I23: Bangladesh
E24: 40 | G24: A010402 | I24: Barbade
E25: 41 | G25: A010403 | I25: Bélarus
E26: 43 | G26: A0201 | I26: Belgique
E27: 49 | G27: A020101 | I27: Belize
E28: 50 | G28: A020102 | I28: Bénin
E29: 52 | G29: A020103 | I29: Bermudes
E30: 53 | G30: A020200 | I30: Bhoutan
E31: 59 | G31: A0203 | I31: Bolivie
E32: 60 | G32: A020300 | I32: Bosnie-Herzégovine
E33: 99 | G33: A0301 | I33: Botswana
G34: A030101 | I34: Brésil
G35: A030102 | I35: Brunéi Darussalam
G36: A0302 | I36: Bulgarie
G37: A030201 | I37: Burkina Faso
G38: A030202 | I38: Burundi
G39: B0500 | I39: Cambodge
G40: B050000 | I40: Cameroun
...

Sheet Export XML
A1: GENERER LE FICHIER XML POUR E-IMPOTS
A5: IMPORTANT : veillez à bien activer les modifications et appliquer les macros ("activer le contenu") à l'ouverture pour pouvoir utiliser ce fichier
D10: Type de liasse | G10: NO
D11: NCC | G11: =SUBSTITUTE(Sommaire!$D$45," ","") | J11: =IF(Q11=0,"Veuillez respecter le format 1234567A, sans espace.","") | Q11: =IF(AND(LEN(G11)<>8,LEN(G11)<>0), 0, 1) -> 1
D12: Exercice | G12: =YEAR(Sommaire!$M$35) -> 1900 | J12: =IF(Q12=0,"Veuillez renseigner un exercice valide.","") | Q12: =IF(OR(LEN(G12)=0,AND(ISNUMBER(G12),LEN(G12)=4)),1,0) -> 1
A14: Comment générer un fichier XML pour e-impots ? | G14: IMPORTANT
A15: #1 | B15: Renseignez votre NCC et l'exercice concerné ci-dessus. | G15: Les onglets grisés (GARDE, RECEVABILITE, FICHE R4, NOTES DGI - INS) et les champs grisés de l'onglet FICHE R1 peuvent être ignorés. Les informations qu'ils contiennent ne seront pas exportées dans le fichier XML.
A16: #2 | B16: Remplissez les onglets du fichier qui vous concernent.
A17: #3 | B17: Cliquez sur le bouton "Générer le fichier XML" ci-dessous.
A18: Comment utiliser le fichier XML géneré ? | G18: La structure de ce fichier ne peut pas être modifiée. Si vous avez besoin d'ajouter des informations supplémentaires, veuillez les ajouter dans l'onglet COMMENTAIRE ou en tant que pièce jointe dans e-impots.
A19: #4 | B19: Le fichier XML géneré est déposé dans le répertoire /Documents de votre poste de travail.
A20: #5 | B20: A l'étape 1 de la déclaration de vos états financiers, vous pouvez charger le fichier dans la section "Import des états financiers au format XML". | G20: Tous les champs déjà saisis dans e-impots seront écrasés lors de l'import.
G21: Tous les montants sont à exprimer en Francs CFA (sauf mention contraire)
D27: Note : La génération peut prendre plusieurs minutes.
E29: Version 1.1 - Juillet 2020

Sheet tableaux
A1: 1. MAPPING DES TABLEAUX
A4: Instructions
A5: Pour chaque tableau de la liste ci-dessous :
A6: Etape 1 Remplir la colonne Onglet avec le nom de l'onglet dans lequel se trouve le tableau dans le fichier Excel | C6: Etape 2 Remplir la colonne Première cellule avec le nom de la première cellule à remplir du tableau | G6: Etape 3 Si le tableau est de type variable, remplir la colonne Dernière cellule avec le nom de la dernière cellule à remplir du tableau
A7: Aide : Pour les tableaux qui se trouvent dans les mêmes onglets et/ou cellules que dans le modèle Excel de la DGI, vous pouvez directement copier les valeurs des colonnes Onglet DGI, Première cellule DGI et Dernière cellule DGI qui sont données à titre indicatif.
A9: Définitions
A11: Colonnes de la liste | F11: Types de tableaux
A12: Colonne | B12: Description | F12: Type de tableau | G12: Description
A13: Code tableau | B13: Le code DGI permettant d'identifier le tableau. | F13: Fixe | G13: Tableau ayant un nombre de lignes fixe (ex : tableau de résultat). | I13: 334
A14: Titre | B14: Le titre du tableau. | F14: Variable | G14: Tableau ayant un nombre de lignes variable (ex : liste des dirigeants).
A15: Type | B15: Le type du tableau (cf. liste ci-contre).
A16: Onglet | B16: Renseigner le nom de la feuille du fichier Excel qui contient le tableau.
A17: Première cellule | B17: Renseigner l'adresse de la première cellule à remplir du tableau (celle située en haut à gauche du tableau).
A18: Dernière cellule | B18: Renseigner l'adresse de la dernière cellule à remplir du tableau (celle située en bas à droite du tableau). Uniquement pour les tableaux variables.
A20: Onglet DGI | B20: Nom de la feuille qui contient le tableau dans le modèle Excel de la DGI.
A21: Première cellule DGI | B21: Adresse de la première cellule du tableau dans le modèle Excel de la DGI.
A22: Dernière cellule DGI | B22: Adresse de la dernière cellule du tableau dans le modèle Excel de la DGI.
A24: Liste des tableaux
A26: Informations d'identification des tableaux | D26: A remplir | G26: Valeurs du modèle Excel de la DGI (données à titre indicatif)
A27: Code tableau | B27: Titre | C27: Type | D27: Onglet | E27: Première cellule | F27: Dernière cellule | G27: Onglet DGI | H27: Première cellule DGI | I27: Dernière cellule DGI
A28: FR1 | B28: Fiche R1 | C28: Fixe | D28: FICHE R1 | E28: C8 | G28: FICHE R1 | H28: C8
A29: FR2A | B29: Fiche R2 - Divers | C29: Fixe | D29: FICHE R2 | E29: Q9 | G29: FICHE R2 | H29: Q9
A30: FR2B | B30: Fiche R2 - Détail de l'activité de l'entité | C30: Variable | D30: FICHE R2 | E30: A28 | F30: =ADDRESS(ROW('FICHE R2'!AH29),COLUMN('FICHE R2'!AH29),4) -> AH29 | G30: FICHE R2 | H30: A28 | I30: AH29
A31: FR2C | B31: Fiche R2 - Unité de mesure de l'activité | C31: Fixe | D31: FICHE R2 | E31: Y25 | G31: FICHE R2 | H31: Y25
A32: FR2D | B32: Fiche R2 - Total de l'activité de l'entité | C32: Fixe | D32: FICHE R2 | E32: =ADDRESS(ROW('FICHE R2'!Y30),COLUMN('FICHE R2'!Y30),4) -> Y30 | G32: FICHE R2 | H32: Y30
A33: FR3A | B33: Fiche R3 - Dirigeants | C33: Variable | D33: FICHE R3 | E33: A11 | F33: =ADDRESS(ROW('FICHE R3'!H11),COLUMN('FICHE R3'!H11),4) -> H11 | G33: FICHE R3 | H33: A11 | I33: H11
A34: FR3B | B34: Fiche R3 - Membres du conseil d'administration | C34: Variable | D34: FICHE R3 | E34: =ADDRESS(ROW('FICHE R3'!A17),COLUMN('FICHE R3'!A17),4) -> A17 | F34: =ADDRESS(ROW('FICHE R3'!G17),COLUMN('FICHE R3'!G17),4) -> G17 | G34: FICHE R3 | H34: A17 | I34: G17
A35: ACTIF | B35: Bilan - Actif | C35: Fixe | D35: ACTIF | E35: F11 | G35: ACTIF | H35: F11
A36: PASSIF | B36: Bilan - Passif | C36: Fixe | D36: PASSIF | E36: H11 | G36: PASSIF | H36: H11
A37: RESULTAT | B37: Résultat | C37: Fixe | D37: RESULTAT | E37: I11 | G37: RESULTAT | H37: I11
A38: TFT | B38: Tableau de flux de trésorerie | C38: Fixe | D38: TFT | E38: I10 | G38: TFT | H38: I10
A39: NOTE1A | B39: Dettes garanties par des sûretés réelles | C39: Fixe | D39: NOTE 1 | E39: F10 | G39: NOTE 1 | H39: F10
A40: NOTE1B | B40: Engagements financiers | C40: Fixe | D40: NOTE 1 | E40: G34 | G40: NOTE 1 | H40: G34
A41: NOTE2 | B41: Informations obligatoires | C41: Fixe | D41: NOTE 2 | E41: A9 | G41: NOTE 2 | H41: A9
A42: NOTE3A | B42: Immobilisations (brutes) | C42: Fixe | D42: NOTE 3A | E42: D11 | G42: NOTE 3A | H42: D11
A43: NOTE3B | B43: Biens pris en location acquisition | C43: Fixe | D43: NOTE 3B | E43: E11 | G43: NOTE 3B | H43: E11
A44: NOTE3C | B44: Immobilisations (amortissements) | C44: Fixe | D44: NOTE 3C | E44: D11 | G44: NOTE 3C | H44: D11
A45: NOTE3CBIS | B45: Immobilisations (dépréciations) | C45: Fixe | D45: NOTE 3C BIS | E45: D11 | G45: NOTE 3C BIS | H45: D11
A46: NOTE3D | B46: Immobilisations (plus-values et moins-values de cession) | C46: Fixe | D46: NOTE 3D | E46: D10 | G46: NOTE 3D | H46: D10
A47: NOTE3E1 | B47: Informations sur les réévaluations effectuées par l'entité | C47: Fixe | D47: NOTE 3E | E47: A9 | G47: NOTE 3E | H47: A9
...

Sheet champs fixes
A1: 2. MAPPING DES CHAMPS FIXES (champs des tableaux à nombre de lignes fixe)
A4: Instructions
A6: Etape 1 Cliquer sur le bouton Générer le mapping pour pré-remplir automatiquement la liste ci-dessous | D6: Etape 2 Pour les lignes de la liste qui le nécessitent, corriger manuellement le mapping du champ en modifiant Position ligne et Position colonne. Ces numéros doivent correspondre à la position de la cellule contenant la valeur du champ par rapport à la position de la première cellule du tableau. | G6: Etape 3 Cliquer sur le bouton Générer le mapping pour obtenir le mapping final
A8: Définitions
A10: Colonnes de la liste
A11: Colonne | B11: Description
A12: Code tableau | B12: Le code DGI permettant d'identifier le tableau auquel le champ appartient.
A13: Code ligne | B13: Le code permettant d'identifier la ligne du tableau où se trouve le champ dans le modèle Excel de la DGI (s'il y en a un).
A14: Libellé ligne | B14: Le libellé e-impots de la ligne du tableau où se trouve le champ.
A15: Libellé colonne | B15: Le libellé e-impots de la colonne du tableau où se trouve le champ.
A16: Code champ | B16: Le code DGI permettant d'identifier le champ.
A17: Position ligne | B17: Le numéro de position de la ligne du tableau où se trouve le champ par rapport à la première cellule du tableau. La valeur pré-remplie est celle correspondant au modèle Excel de la DGI.
A18: Position colonne | B18: Le numéro de position de la colonne du tableau où se trouve le champ par rapport à la première cellule du tableau. La valeur pré-remplie est celle correspondant au modèle Excel de la DGI.
A19: Cellule | B19: L'adresse de la cellule contenant la valeur du champ.
A20: Valeur | B20: La valeur du champ saisie dans le fichier (si le champ a été rempli).
A22: Liste des champs de tableaux fixes
A27: Informations d'identification des champs | F27: A modifier si nécessaire | H27: Mapping généré
A28: Code tableau | B28: Code ligne | C28: Libellé ligne | D28: Libellé colonne | E28: Code champ | F28: Position ligne | G28: Position colonne | H28: Cellule | I28: Valeur
A29: FR1 | B29: ZA | C29: DATE DE DEBUT DE L'EXERCICE COMPTABLE | D29: Valeurs | E29: NO_FR1_ZA1_1 | F29: 1 | G29: 12 | H29: N8
A30: FR1 | B30: ZA | C30: DATE DE FIN DE L'EXERCICE COMPTABLE | D30: Valeurs | E30: NO_FR1_ZA2_1 | F30: 1 | G30: 17 | H30: S8
A31: FR1 | B31: ZB | C31: DATE D'ARRETE EFFECTIF DES COMPTES | D31: Valeurs | E31: NO_FR1_ZB_1 | F31: 3 | G31: 6 | H31: H10
A32: FR1 | B32: ZC | C32: EXERCICE PRECEDENT CLOS LE | D32: Valeurs | E32: NO_FR1_ZC_1 | F32: 5 | G32: 6 | H32: H12
A33: FR1 | B33: ZD | C33: DUREE EXERCICE PRECEDENT EN MOIS | D33: Valeurs | E33: NO_FR1_ZD_1 | F33: 5 | G33: 19 | H33: U12
A34: FR1 | B34: ZE | C34: Greffe | D34: Valeurs | E34: NO_FR1_ZE1_1 | F34: 7 | G34: 1 | H34: C14
A35: FR1 | B35: ZE | C35: N°Registre du Commerce | D35: Valeurs | E35: NO_FR1_ZE2_1 | F35: 7 | G35: 2 | H35: D14
A36: FR1 | B36: ZF | C36: N° Répertoire des entités | D36: Valeurs | E36: NO_FR1_ZF_1 | F36: 7 | G36: 9 | H36: K14
A37: FR1 | B37: ZG | C37: N° de caisse sociale | D37: Valeurs | E37: NO_FR1_ZG_1 | F37: 10 | G37: 1 | H37: C17
A38: FR1 | B38: ZH | C38: N° Code Importateur | D38: Valeurs | E38: NO_FR1_ZH_1 | F38: 10 | G38: 4 | H38: F17
A39: FR1 | B39: ZI | C39: Code activité principale | D39: Valeurs | E39: NO_FR1_ZI_1 | F39: 10 | G39: 15 | H39: Q17
A40: FR1 | B40: ZK | C40: Adresse e-mail | D40: Valeurs | E40: NO_FR1_ZK1_1 | F40: 16 | G40: 3 | H40: E23
... A64: FR2A | B64: ZZ4 | C64: Première année d'exercice dans le pays : | D64: Valeurs | E64: NO_FR2A_ZZ4_1 | F64: 12 | G64: 1 | H64: Q20
A65: FR2A | C65: Contrôle de l'entité | D65: Valeurs | E65: NO_FR2A_1_1 | F65: 3 | G65: 7 | H65: W11
A66: FR2C | C66: Unité de mesure de l'activité | D66: Valeurs | E66: NO_FR2C_1_1 | F66: 1 | G66: 1 | H66: Y25
A67: FR2D | C67: Total de l'activité de l'entité | D67: Chiffre d'affaires HT ou Valeur ajoutée (VA) | E67: NO_FR2D_1_1 | F67: 1 | G67: 1 | H67: Y30 | I67: 0
A68: FR2D | C68: Total de l'activité de l'entité | D68: % activité dans le CA HT ou la VA | E68: NO_FR2D_1_2 | F68: 1 | G68: 10 | H68: AH30 | I68: 0,00%
A69: ACTIF | B69: AD | C69: IMMOBILISATIONS INCORPORELLES | D69: BRUT | E69: NO_ACTIF_AD_1 | F69: 1 | G69: 1 | H69: F11
A70: ACTIF | B70: AD | C70: IMMOBILISATIONS INCORPORELLES | D70: AMORT et DEPREC. | E70: NO_ACTIF_AD_2 | F70: 1 | G70: 2 | H70: G11
A71: ACTIF | B71: AD | C71: IMMOBILISATIONS INCORPORELLES | D71: NET | E71: NO_ACTIF_AD_3 | F71: 1 | G71: 3 | H71: H11
A72: ACTIF | B72: AD | C72: IMMOBILISATIONS INCORPORELLES | D72: NET (N-1) | E72: NO_ACTIF_AD_4 | F72: 1 | G72: 4 | H72: I11
A73: ACTIF | B73: AE | C73: Frais de développement et de prospection | D73: BRUT | E73: NO_ACTIF_AE_1 | F73: 2 | G73: 1 | H73: F12
...

Sheet champs variables
A1: 3. MAPPING DES CHAMPS VARIABLES (champs des tableaux à nombre de lignes variable)
A4: Instructions
A6: Etape 1 Cliquer sur le bouton Générer le mapping pour pré-remplir automatiquement la liste ci-dessous | B6: Etape 2 Pour les lignes de la liste qui le nécessitent, corriger manuellement le mapping en modifiant Position colonne. Ce numéro doit correspondre à la position de la colonne par rapport à la position de la première cellule du tableau. | D6: Etape 3 Cliquer sur le bouton Générer le mapping pour obtenir le mapping final
A8: Définitions
A10: Colonnes de la liste
A11: Colonne | B11: Description
A12: Code tableau | B12: Le code DGI permettant d'identifier le tableau auquel la colonne appartient.
A13: Libellé colonne | B13: Le libellé e-impots de la colonne.
A14: Code colonne | B14: Le code DGI permettant d'identifier la colonne.
A15: Position colonne | B15: Le numéro de position de la colonne dans le fichier par rapport à la première cellule du tableau. La valeur pré-remplie est celle correspondant au modèle Excel de la DGI.
A16: Cellule | B16: L'adresse de la cellule contenant la valeur du premier champ de la colonne.
A18: Liste des colonnes de tableaux variables
A23: Informations d'identification des colonnes | D23: A modifier si nécessaire | E23: Mapping généré
A24: Code tableau | B24: Libellé colonne | C24: Code colonne | D24: Position colonne | E24: Cellule
A25: FR2B | B25: Désignation de l'activité | C25: NO_FR2B_1 | D25: 1 | E25: A28
A26: FR2B | B26: Code nomenclature d'activité | C26: NO_FR2B_2 | D26: 16 | E26: P28
A27: FR2B | B27: Chiffre d'affaires HT (CA HT) ou Valeur ajoutée (VA) | C27: NO_FR2B_3 | D27: 25 | E27: Y28
A28: FR2B | B28: % activité dans le CA HT ou la VA | C28: NO_FR2B_4 | D28: 34 | E28: AH28
A29: FR3A | B29: Nom et Prénoms | C29: NO_FR3A_1 | D29: 1 | E29: A11
A30: FR3A | B30: Nationalité | C30: NO_FR3A_2 | D30: 3 | E30: C11
A31: FR3A | B31: Autres nationalités (2) | C31: NO_FR3A_3 | D31: 4 | E31: D11
A32: FR3A | B32: Qualité (1) | C32: NO_FR3A_4 | D32: 5 | E32: E11
A33: FR3A | B33: N° d'identification fiscale | C33: NO_FR3A_5 | D33: 6 | E33: F11
A34: FR3A | B34: Adresse (BP, ville, pays, adresse géographique et adresse email) | C34: NO_FR3A_6 | D34: 8 | E34: H11
A35: FR3B | B35: Nom et Prénoms | C35: NO_FR3B_1 | D35: 1 | E35: A17
A36: FR3B | B36: Structure représentée | C36: NO_FR3B_2 | D36: 3 | E36: C17
... A159: SUPPL7B | B159: INTERETS | C159: NO_SUPPL7B_3 | D159: 9 | E159: I11

Sheet export
A1: 4. VERIFICATION DU MAPPING
A4: Instructions
A6: Etape 1 Remplir les champs de la liasse avec des valeurs | C6: Etape 2 Cliquer sur le bouton Récupérer les champs remplis pour obtenir les valeurs récupérées grâce au mapping | E6: Etape 3 Vérifier que les valeurs des champs de la liasse qui ont été remplis ont bien été récupérées. Corriger le mapping si ce n'est pas le cas.
A8: Contenu de la liasse récupéré grâce au mapping
A10: Type de liasse | B10: NCC | C10: Exercice
A11: ='Export XML'!G10 -> NO | B11: ='Export XML'!G11 | C11: ='Export XML'!G12 -> 1900
A13: Valeurs remplies dans les champs variables | E13: Valeurs remplies dans les champs fixes
A14: Code colonne | B14: Ligne | C14: Valeur | E14: Code champ | F14: Valeur
A15: NO_FR2B_1 | B15: 2 | C15: Divers | E15: NO_FR1_ZA1_1 | F15: 01/01/2019
A16: NO_NOTE13B_1 | B16: 2 | C16: Apporteurs, capital non appelé | E16: NO_FR1_ZA2_1 | F16: 31/12/2019
A17: NO_NOTE32_1 | B17: 2 | C17: NON VENTILE | E17: NO_FR1_ZB_1 | F17: 25/03/2020
A18: NO_NOTE33_1 | B18: 2 | C18: NON VENTILE | E18: NO_FR1_ZC_1 | F18: 31/12/2019
A19: NO_SUPPL1B_1 | B19: 52 | C19: NON VENTILE | E19: NO_FR1_ZD_1 | F19: 12
E20: NO_FR1_ZE1_1 | F20: ABJ
E21: NO_FR1_ZE2_1 | F21: CI-ABJ-2020-B-04044
E22: NO_FR1_ZG_1 | F22: 362401
E23: NO_FR1_ZI_1 | F23: J620002
E24: NO_FR1_ZK1_1 | F24: info@befils.com
E25: NO_FR1_ZK2_1 | F25: 08
E26: NO_FR1_ZK3_1 | F26: 3181
E27: NO_FR1_ZK4_1 | F27: ABIDJAN
E28: NO_FR1_ZL_1 | F28: YOPOUGON BATIM
E29: NO_FR2A_ZX_1 | F29: 03
E30: NO_FR2A_ZY_1 | F30: 2
E31: NO_FR2A_ZZ1_1 | F31: 03
E32: NO_FR2A_ZZ4_1 | F32: 2018
E33: NO_NOTE34_31_3 | F33: 0 points
E34: NO_NOTE34_32_3 | F34: 0 points
E35: NO_NOTE37_28_1 | F35: 0.25

Sheet Sommaire
B2: SOMMAIRE | O2: ETATS COMPLEMENTAIRES
B4: TABLE DE CONVERSION | F4: NOTE 3E - INFORMATIONS SUR LES REEVALUATIONS EFFEC | I4: FALSE | J4: =IF(I4=TRUE,1,0) -> 0 | K4: NOTE 18 - DETTES FISCALES ET SOCIALES | M4: TRUE | N4: =IF(M4=TRUE,1,0) -> 1 | O4: NOTES DGI - INS - FICHE RECAPITULATIVE DES ETATS S | R4: TRUE
B5: COUVERTURE | D5: TRUE | E5: =IF(D5=TRUE,1,0) -> 1 | F5: NOTE 4 - IMMOBILISATIONS FINANCIERES | I5: FALSE | J5: =IF(I5=TRUE,1,0) -> 0 | K5: NOTE 19 - AUTRES DETTES ET PROVISIONS POUR RISQUES | M5: FALSE | N5: =IF(M5=TRUE,1,0) -> 0 | O5: COMP-CHARGES - DETAIL DES CHARGES | R5: TRUE
B6: GARDE | D6: TRUE | E6: =IF(D6=TRUE,1,0) -> 1 | F6: NOTE 5 - ACTIF CIRCULANT ET DETTES CIRCULANTES HA | I6: FALSE | J6: =IF(I6=TRUE,1,0) -> 0 | K6: NOTE 20 - BANQUES, CREDIT D'ESCOMPTE ET DE TRESORE | M6: TRUE | N6: =IF(M6=TRUE,1,0) -> 1 | O6: COMP-TVA - ETAT TVA | R6: TRUE
B7: RECEVABILITE | D7: TRUE | E7: =IF(D7=TRUE,1,0) -> 1 | F7: NOTE 6 - STOCKS ET ENCOURS | I7: FALSE | J7: =IF(I7=TRUE,1,0) -> 0 | K7: NOTE 21 - CHIFFRE D'AFFAIRES ET AUTRES PRODUITS | M7: TRUE | N7: =IF(M7=TRUE,1,0) -> 1 | O7: COMP-TVA (2) - ETAT TVA SUPPORTE NON DEDUCTIBLE | R7: TRUE
B8: NOTE36 - TABLE DES CODES | D8: TRUE | E8: =IF(D8=TRUE,1,0) -> 1 | F8: NOTE 7 - CLIENTS | I8: FALSE | J8: =IF(I8=TRUE,1,0) -> 0 | K8: NOTE 22 - ACHATS | M8: TRUE | N8: =IF(M8=TRUE,1,0) -> 1 | O8: SUPPL1 - ELEMENTS STATISTIQUES UEMOA | R8: FALSE
B9: NOTE36 Suite - Nomenclature | D9: TRUE | E9: =IF(D9=TRUE,1,0) -> 1 | F9: NOTE 8 - AUTRES CREANCES | I9: FALSE | J9: =IF(I9=TRUE,1,0) -> 0 | K9: NOTE 23 - TRANSPORTS | M9: TRUE | N9: =IF(M9=TRUE,1,0) -> 1 | O9: SUPPL2 - REPARTITION DU RESULTAT FISCAL DES SOCIET | R9: FALSE | U9: Contacts
B10: FICHE R1 - FICHE IDENTIFICATION ET RENS. DIVERS 1 | D10: TRUE | E10: =IF(D10=TRUE,1,0) -> 1 | F10: NOTE 8A - TAB D’ETALEMENT DES CHARGES IMMOBILISEES | I10: FALSE | J10: =IF(I10=TRUE,1,0) -> 0 | K10: NOTE 24 - SERVICES EXTERIEURS | M10: TRUE | N10: =IF(M10=TRUE,1,0) -> 1 | O10: SUPPL3 - COMPLEMENT INFORMATIONS ENTITES INDIVIDUE | R10: FALSE
B11: FICHE R2 - FICHE IDENTIFICATION ET RENS. DIVERS 2 | D11: TRUE | E11: =IF(D11=TRUE,1,0) -> 1 | F11: NOTE 8B - TAB D’ETALEMENT DES PROVISIONS POUR CHAR | I11: FALSE | J11: =IF(I11=TRUE,1,0) -> 0 | K11: NOTE 25 - IMPOTS ET TAXES | M11: TRUE | N11: =IF(M11=TRUE,1,0) -> 1 | O11: SUPPL4 - TABLEAU DES AMORTISSEMENTS ET INVENTAIRE | R11: TRUE | U11: +225 77 23 23 25
B12: FICHE R3 - FICHE IDENTIFICATION ET RENS. DIVERS 3 | D12: TRUE | E12: =IF(D12=TRUE,1,0) -> 1 | F12: NOTE 8C - TAB D'ETALEMENT DES PROVISIONS POUR ENGA | I12: FALSE | J12: =IF(I12=TRUE,1,0) -> 0 | K12: NOTE 26 - AUTRES CHARGES | M12: FALSE | N12: =IF(M12=TRUE,1,0) -> 0 | O12: SUPPL5 - DETAIL DES FRAIS ACCESSOIRES SUR ACHATS | R12: FALSE | U12: +225 74 64 44 91
B13: BILAN | D13: TRUE | E13: =IF(D13=TRUE,1,0) -> 1 | F13: NOTE 9 - TITRES DE PLACEMENT | I13: FALSE | J13: =IF(I13=TRUE,1,0) -> 0 | K13: NOTE 27A - CHARGES DE PERSONNEL | M13: TRUE | N13: =IF(M13=TRUE,1,0) -> 1 | O13: SUPPL6 - DETAIL DES AVANTAGES EN NATURE ET EN ESPE | R13: FALSE | U13: +225 20 35 31 73
B14: BILAN - ACTIF | D14: TRUE | E14: =IF(D14=TRUE,1,0) -> 1 | F14: NOTE 10 - VALEURS A ENCAISSER | I14: FALSE | J14: =IF(I14=TRUE,1,0) -> 0 | K14: NOTE 27B - EFFECTIFS, MASSE SALARIALE ET PERSONNEL | M14: TRUE | N14: =IF(M14=TRUE,1,0) -> 1 | O14: SUPPL7 - CREANCES & DETTES ECHUES DE L'EXERCICE | R14: TRUE | U14: info@befils.com
B15: BILAN - PASSIF | D15: TRUE | E15: =IF(D15=TRUE,1,0) -> 1 | F15: NOTE 11 - DISPONIBILITES | I15: TRUE | J15: =IF(I15=TRUE,1,0) -> 1 | K15: NOTE 28 - DOTATIONS ET CHARGES POUR PROVISIONS ET | M15: TRUE | N15: =IF(M15=TRUE,1,0) -> 1 | O15: COMMENTAIRE | R15: TRUE
B16: COMPTE DE RESULTAT | D16: TRUE | E16: =IF(D16=TRUE,1,0) -> 1 | F16: NOTE 12 - ECARTS DE CONVERSION ET TRANSFERT DE CHA | I16: FALSE | J16: =IF(I16=TRUE,1,0) -> 0 | K16: NOTE 29 - CHARGES ET REVENUS FINANCIERS | M16: FALSE | N16: =IF(M16=TRUE,1,0) -> 0
B17: TABLEAU DES FLUX DE TRESORERIE | D17: TRUE | E17: =IF(D17=TRUE,1,0) -> 1 | F17: NOTE 13 - CAPITAL : VALEUR NOMINALE DES ACTIONS OU | I17: TRUE | J17: =IF(I17=TRUE,1,0) -> 1 | K17: NOTE 30 - AUTRES CHARGES ET PRODUITS HAO | M17: FALSE | N17: =IF(M17=TRUE,1,0) -> 0 | O17: IMPORTANT !!! -------------------------------------------- Merci cocher les feuilles à imprimer. Seules les feuilles cochées ici seront imprimées
B18: FICHE R4 - FICHE RECAPITULATIVE DES NOTES ANNEXES | D18: TRUE | E18: =IF(D18=TRUE,1,0) -> 1 | F18: NOTE 14 - PRIMES ET RESERVES | I18: TRUE | J18: =IF(I18=TRUE,1,0) -> 1 | K18: NOTE 31 - REPARTITION DU RESULTAT ET AUTRES ELEMEN | M18: TRUE | N18: =IF(M18=TRUE,1,0) -> 1
B19: NOTE 1 - DETTES GARANTIES PAR DES SURETES REELLES | D19: FALSE | E19: =IF(D19=TRUE,1,0) -> 0 | F19: NOTE 15A - SUBVENTIONS ET PROVISIONS REGLEMENTEES | I19: FALSE | J19: =IF(I19=TRUE,1,0) -> 0 | K19: NOTE 32 - PRODUCTION DE L'EXERCICE | M19: FALSE | N19: =IF(M19=TRUE,1,0) -> 0
B20: NOTE 2 - INFORMATIONS OBLIGATOIRES | D20: FALSE | E20: =IF(D20=TRUE,1,0) -> 0 | F20: NOTE 15B - AUTRES FONDS PROPRES | I20: FALSE | J20: =IF(I20=TRUE,1,0) -> 0 | K20: NOTE 33 - ACHATS DESTINES A LA PRODUCTION | M20: FALSE | N20: =IF(M20=TRUE,1,0) -> 0
B21: NOTE 3A - IMMOBILISATIONS BRUTES | D21: TRUE | E21: =IF(D21=TRUE,1,0) -> 1 | F21: NOTE 16A - DETTES FINANCIERES ET RESSOURCES ASSIMI | I21: TRUE | J21: =IF(I21=TRUE,1,0) -> 1 | K21: NOTE 34 - FICHE DE SYNTHESE DES PRINCIPAUX INDICAT | M21: TRUE | N21: =IF(M21=TRUE,1,0) -> 1
B22: NOTE 3B - BIENS PRIS EN LOCATION-ACQUISITION | D22: FALSE | E22: =IF(D22=TRUE,1,0) -> 0 | F22: NOTE 16B - ENGAGEMENTS DE RETRAITE ET AVANTAGES AS | I22: FALSE | J22: =IF(I22=TRUE,1,0) -> 0 | K22: NOTE 35 - LISTE DES INFORMATIONS SOCIALES, ENVIRON | M22: FALSE | N22: =IF(M22=TRUE,1,0) -> 0 | T22: =IF(OR(Code!$R$6=Code!$S$6,Code!$U$6="vert"),"","Veuillez saisir la clé d'activation Pour activer les calculs automatiques")
B23: NOTE 3C - IMMOBILISATIONS : AMORTISSEMENTS | D23: TRUE | E23: =IF(D23=TRUE,1,0) -> 1 | F23: NOTE 16B BIS - ENGAGEMENTS DE RETRAITE ET AVANTAGE | I23: FALSE | J23: =IF(I23=TRUE,1,0) -> 0 | K23: NOTE 37 - DETERMINATION IMPOT SUR RESULTAT | M23: TRUE | N23: =IF(M23=TRUE,1,0) -> 1
B24: NOTE 3C BIS - IMMOBILISATIONS : DEPRECIATIONS | D24: FALSE | E24: =IF(D24=TRUE,1,0) -> 0 | F24: NOTE 16C - ACTIFS ET PASSIFS EVENTUELS | I24: FALSE | J24: =IF(I24=TRUE,1,0) -> 0 | K24: NOTE 38 - EVENEMENTS POSTERIEURS A LA CLOTURE DE L | M24: FALSE
B25: NOTE 3D - IMMOBILISATIONS : PLUS-VALUES ET MOINS V | D25: FALSE | E25: =IF(D25=TRUE,1,0) -> 0 | F25: NOTE 17 - FOURNISSEURS D'EXPLOITATION | I25: TRUE | J25: =IF(I25=TRUE,1,0) -> 1 | K25: NOTE 39 - CHANGEMENTS DE METHODES COMPTABLES, D’ES | M25: FALSE | N25: =IF(M25=TRUE,1,0) -> 0
B27: Dénomination sociale de l'entreprise : | D27: OHADA | K27: N° de caisse sociale :
B29: Sigle usuel : | K29: N° répertoire des entreprises
B31: Agrément prioritaire : | K31: N° Code Importateur :
B33: Forme juridique : | K33: N° de téléphone / Email
B35: Si autre forme juridique préciser | K35: Exercice du :
B37: Désignation de l'activité | K37: Exercice précédent du :
B39: Boîte Postale de l'entreprise : | K39: Date d'arrêt des comptes :
B41: Commune / Quartier : | K41: Année du premier exercice :
B43: Greffe / N° Registre du Commerce | K43: Taux d'imposition BIC / BNC | M43: 0.25
B45: N° Identification fiscale / Télédéclarant: | K45: Taux IMF | M45: 0.005
B47: Regime Fiscal / Centre des Impôts :
B49: Pays Siège social / Code activité principale

Sheet TABLE DE CONVERSION
A1: ="BALANCE A 6 COLONNES DE L'EXERCICE "&TEXT(Sommaire!Q35,"yyyy") -> BALANCE A 6 COLONNES DE L'EXERCICE 1900 | M1: =IF(AND(A3="",A4="",N3="",N4=""),0,1) -> 0 | N1: ="BALANCE A 6 COLONNES DE L'EXERCICE "&TEXT(Sommaire!Q37,"yyyy") -> BALANCE A 6 COLONNES DE L'EXERCICE 1900
A2: ="Veuillez copier et coller en valeur votre balance à 6 colonnes de l'exercice "&TEXT(Sommaire!Q35,"yyyy") -> Veuillez copier et coller en valeur votre balance à 6 colonnes de l'exercice 1900 | N2: ="Veuillez copier et coller en valeur votre balance à 6 colonnes de l'exercice "&TEXT(Sommaire!Q37,"yyyy") -> Veuillez copier et coller en valeur votre balance à 6 colonnes de l'exercice 1900
A3: =IF(COUNTIF(BalanceN[Vérif],"A")=0,"","Veuillez vérifier le numéro de comptes des Lignes surlignés en rouges en tenant compte du plan comptable OHADA Révisé") | N3: =IF(COUNTIF(BalanceN1[Vérif],"A")=0,"","Veuillez vérifier le numéro de comptes des Lignes surlignés en rouges en tenant compte du plan comptable OHADA Révisé")
A4: =IF(AND(COUNTIF(BalanceN[SF],"A")=0,COUNTIF(BalanceN[SI],"A")=0),"","Veuillez corriger l'imputation des comptes des Lignes surlignés en orange (Voir Balance d'entrée et/ou balance sortie)") | N4: =IF(AND(COUNTIF(BalanceN1[SF],"A")=0,COUNTIF(BalanceN1[SI],"A")=0),"","Veuillez corriger l'imputation des comptes des Lignes surlignés en orange (Voir Balance d'entrée et/ou balance sortie)")
A5: =IF(AND(M5=M6,Z5=Z6),"","Balance d'entrée "&TEXT(Sommaire!Q35,"yyyy")&" différent de Balance de sortie "&TEXT(Sommaire!Q37,"yyyy")) | M5: =SUMIFS(BalanceN[BE_Debit],BalanceN[Table],">=10000",BalanceN[Table],"<60000") -> 825656309 | Z5: =SUMIFS(BalanceN[BE_Credit],BalanceN[Table],">=10000",BalanceN[Table],"<60000") -> 825656309
A6: =IF(OR('Table TFT'!B36<>"",'Table TFT'!B37<>"",'Table TFT'!B38<>"",'Table TFT'!B39<>"",'Table TFT'!B40<>"",'Table TFT'!B41<>"",'Table TFT'!B42<>"",'Table TFT'!B43<>""),"Attention, veuillez remplir la Table TFT de l'exercice "&TEXT(Sommaire!Q35,"yyyy"),"") | M6: =IF( SUMIFS(BalanceN1[BS_Credit],BalanceN1[Table],">=60000",BalanceN1[Table],"<90000") >= SUMIFS(BalanceN1[BS_Debit],BalanceN1[Table],">=60000",BalanceN1[Table],"<90000"), SUMIFS(BalanceN1[BS_Debit],BalanceN1[Table],">=10000",BalanceN1[Table],"<60000"), SUMIFS(BalanceN1[BS_Debit],BalanceN1[Table],">=10000",BalanceN1[Table],"<60000") + SUMIFS(BalanceN1[BS_Debit],BalanceN1[Table],">=60000",BalanceN1[Table],"<90000") - SUMIFS(BalanceN1[BS_Credit],BalanceN1[Table],">=60000",BalanceN1[Table],"<90000") ) -> 825656309 | N6: =IF(OR('Table TFT'!K36<>"",'Table TFT'!K37<>"",'Table TFT'!K38<>"",'Table TFT'!K39<>"",'Table TFT'!K40<>"",'Table TFT'!K41<>"",'Table TFT'!K42<>"",'Table TFT'!K43<>""),"Attention, veuillez remplir Attention, veuillez remplir la Table TFT de l'exercice "&TEXT(Sommaire!AD35,"yyyy"),"") | Z6: =IF( SUMIFS(BalanceN1[BS_Credit],BalanceN1[Table],">=60000",BalanceN1[Table],"<90000") >= SUMIFS(BalanceN1[BS_Debit],BalanceN1[Table],">=60000",BalanceN1[Table],"<90000"), SUMIFS(BalanceN1[BS_Credit],BalanceN1[Table],">=10000",BalanceN1[Table],"<60000") + SUMIFS(BalanceN1[BS_Credit],BalanceN1[Table],">=60000",BalanceN1[Table],"<90000") - SUMIFS(BalanceN1[BS_Debit],BalanceN1[Table],">=60000",BalanceN1[Table],"<90000"), SUMIFS(BalanceN1[BS_Credit],BalanceN1[Table],">=10000",BalanceN1[Table],"<60000")) -> 825656309
B7: =IF(AND(C7=D7,E7=F7,G7=H7),"","Attention la balance n'est pas équilibré") | C7: =SUM(BalanceN[BE_Debit]) -> 825656309 | D7: =SUM(BalanceN[BE_Credit]) -> 825656309 | E7: =SUM(BalanceN[Mvt_Debit]) -> 9736437162 | F7: =SUM(BalanceN[Mvt_Credit]) -> 9736437162 | G7: =SUM(BalanceN[BS_Debit]) -> 3382628833 | H7: =SUM(BalanceN[BS_Credit]) -> 3382628833 | O7: =IF(AND(P7=Q7,R7=S7,T7=U7),"","Attention la balance n'est pas équilibré") | P7: =SUM(BalanceN1[BE_Debit]) -> 743900145 | Q7: =SUM(BalanceN1[BE_Credit]) -> 743900145 | R7: =SUM(BalanceN1[Mvt_Debit]) -> 7011264571 | S7: =SUM(BalanceN1[Mvt_Credit]) -> 7011264571 | T7: =SUM(BalanceN1[BS_Debit]) -> 2613872627 | U7: =SUM(BalanceN1[BS_Credit]) -> 2613872627
A8: Compte | B8: Désignation | C8: BE_Debit | D8: BE_Credit | E8: Mvt_Debit | F8: Mvt_Credit | G8: BS_Debit | H8: BS_Credit | I8: Table | J8: Vérif | K8: SI | L8: SF | N8: Compte | O8: Désignation | P8: BE_Debit | Q8: BE_Credit | R8: Mvt_Debit | S8: Mvt_Credit | T8: BS_Debit | U8: BS_Credit | V8: Table | W8: Vérif | X8: SI | Y8: SF
A9: 101100 | B9: Capital souscrit, non appelé | E9: 200000000 | F9: 300000000 | H9: 100000000 | I9: =VALUE(LEFT(BalanceN[[#This Row],[Compte]]&"00000000",5)) -> 10110 | J9: {=IF(BalanceN[[#This Row],[Compte]]="",0,_xlfn.IFNA(INDEX(Plan_Comptable[[Table de Compte]:[Sens]],MATCH(VALUE(LEFT(BalanceN[[#This Row],[Table]],4)),VALUE(Plan_Comptable[Table de Compte]),0),2),"A"))} -> 0 | K9: =IF(AND(BalanceN[[#This Row],[Vérif]]="D",BalanceN[[#This Row],[BS_Credit]]>0),"A",IF(AND(BalanceN[[#This Row],[Vérif]]="C",BalanceN[[#This Row],[BS_Debit]]>0),"A","")) | L9: =IF(AND(BalanceN[[#This Row],[Vérif]]="D",BalanceN[[#This Row],[BE_Credit]]>0),"A",IF(AND(BalanceN[[#This Row],[Vérif]]="C",BalanceN[[#This Row],[BE_Debit]]>0),"A","")) | N9: 101300 | O9: Capital souscrit, appelé, versé, oon amorti | Q9: 100000000 | U9: 100000000 | V9: =VALUE(LEFT(BalanceN1[[#This Row],[Compte]]&"00000000",5)) -> 10130 | W9: {=IF(BalanceN1[[#This Row],[Compte]]="",0,_xlfn.IFNA(INDEX(Plan_Comptable[[Table de Compte]:[Sens]],MATCH(VALUE(LEFT(BalanceN1[[#This Row],[Table]],4)),VALUE(Plan_Comptable[Table de Compte]),0),2),"A"))} -> 0 | X9: =IF(AND(BalanceN1[[#This Row],[Vérif]]="D",BalanceN1[[#This Row],[BS_Credit]]>0),"A",IF(AND(BalanceN1[[#This Row],[Vérif]]="C",BalanceN1[[#This Row],[BS_Debit]]>0),"A","")) | Y9: =IF(AND(BalanceN1[[#This Row],[Vérif]]="D",BalanceN1[[#This Row],[BE_Credit]]>0),"A",IF(AND(BalanceN1[[#This Row],[Vérif]]="C",BalanceN1[[#This Row],[BE_Debit]]>0),"A",""))
A10: 101200 | B10: Capital souscrit, appelé, non versé | E10: 200000000 | F10: 200000000 | I10: =VALUE(LEFT(BalanceN[[#This Row],[Compte]]&"00000000",5)) -> 10120 | J10: {=IF(BalanceN[[#This Row],[Compte]]="",0,_xlfn.IFNA(INDEX(Plan_Comptable[[Table de Compte]:[Sens]],MATCH(VALUE(LEFT(BalanceN[[#This Row],[Table]],4)),VALUE(Plan_Comptable[Table de Compte]),0),2),"A"))} -> 0 | K10: =IF(AND(BalanceN[[#This Row],[Vérif]]="D",BalanceN[[#This Row],[BS_Credit]]>0),"A",IF(AND(BalanceN[[#This Row],[Vérif]]="C",BalanceN[[#This Row],[BS_Debit]]>0),"A","")) | L10: =IF(AND(BalanceN[[#This Row],[Vérif]]="D",BalanceN[[#This Row],[BE_Credit]]>0),"A",IF(AND(BalanceN[[#This Row],[Vérif]]="C",BalanceN[[#This Row],[BE_Debit]]>0),"A","")) | N10: 111000 | O10: Réserve légale | Q10: 20000000 | U10: 20000000 | V10: =VALUE(LEFT(BalanceN1[[#This Row],[Compte]]&"00000000",5)) -> 11100 | W10: {=IF(BalanceN1[[#This Row],[Compte]]="",0,_xlfn.IFNA(INDEX(Plan_Comptable[[Table de Compte]:[Sens]],MATCH(VALUE(LEFT(BalanceN1[[#This Row],[Table]],4)),VALUE(Plan_Comptable[Table de Compte]),0),2),"A"))} -> 0 | X10: =IF(AND(BalanceN1[[#This Row],[Vérif]]="D",BalanceN1[[#This Row],[BS_Credit]]>0),"A",IF(AND(BalanceN1[[#This Row],[Vérif]]="C",BalanceN1[[#This Row],[BS_Debit]]>0),"A","")) | Y10: =IF(AND(BalanceN1[[#This Row],[Vérif]]="D",BalanceN1[[#This Row],[BE_Credit]]>0),"A",IF(AND(BalanceN1[[#This Row],[Vérif]]="C",BalanceN1[[#This Row],[BE_Debit]]>0),"A",""))
A11: 101300 | B11: Capital souscrit, appelé, versé non amorti | D11: 100000000 | F11: 200000000 | H11: 300000000 | I11: =VALUE(LEFT(BalanceN[[#This Row],[Compte]]&"00000000",5)) -> 10130 | J11: {=IF(BalanceN[[#This Row],[Compte]]="",0,_xlfn.IFNA(INDEX(Plan_Comptable[[Table de Compte]:[Sens]],MATCH(VALUE(LEFT(BalanceN[[#This Row],[Table]],4)),VALUE(Plan_Comptable[Table de Compte]),0),2),"A"))} -> 0 | K11: =IF(AND(BalanceN[[#This Row],[Vérif]]="D",BalanceN[[#This Row],[BS_Credit]]>0),"A",IF(AND(BalanceN[[#This Row],[Vérif]]="C",BalanceN[[#This Row],[BS_Debit]]>0),"A","")) | L11: =IF(AND(BalanceN[[#This Row],[Vérif]]="D",BalanceN[[#This Row],[BE_Credit]]>0),"A",IF(AND(BalanceN[[#This Row],[Vérif]]="C",BalanceN[[#This Row],[BE_Debit]]>0),"A","")) | N11: 121 | O11: Report à nouveau | Q11: 20818799 | S11: 26631518 | U11: 47450317 | V11: =VALUE(LEFT(BalanceN1[[#This Row],[Compte]]&"00000000",5)) -> 12100 | W11: {=IF(BalanceN1[[#This Row],[Compte]]="",0,_xlfn.IFNA(INDEX(Plan_Comptable[[Table de Compte]:[Sens]],MATCH(VALUE(LEFT(BalanceN1[[#This Row],[Table]],4)),VALUE(Plan_Comptable[Table de Compte]),0),2),"A"))} -> 0 | X11: =IF(AND(BalanceN1[[#This Row],[Vérif]]="D",BalanceN1[[#This Row],[BS_Credit]]>0),"A",IF(AND(BalanceN1[[#This Row],[Vérif]]="C",BalanceN1[[#This Row],[BS_Debit]]>0),"A","")) | Y11: =IF(AND(BalanceN1[[#This Row],[Vérif]]="D",BalanceN1[[#This Row],[BE_Credit]]>0),"A",IF(AND(BalanceN1[[#This Row],[Vérif]]="C",BalanceN1[[#This Row],[BE_Debit]]>0),"A",""))
A12: 106200 | B12: Ecarts de réévaluation | F12: 3500000 | H12: 3500000 | I12: =VALUE(LEFT(BalanceN[[#This Row],[Compte]]&"00000000",5)) -> 10620 | J12: {=IF(BalanceN[[#This Row],[Compte]]="",0,_xlfn.IFNA(INDEX(Plan_Comptable[[Table de Compte]:[Sens]],MATCH(VALUE(LEFT(BalanceN[[#This Row],[Table]],4)),VALUE(Plan_Comptable[Table de Compte]),0),2),"A"))} -> 0 | K12: =IF(AND(BalanceN[[#This Row],[Vérif]]="D",BalanceN[[#This Row],[BS_Credit]]>0),"A",IF(AND(BalanceN[[#This Row],[Vérif]]="C",BalanceN[[#This Row],[BS_Debit]]>0),"A","")) | L12: =IF(AND(BalanceN[[#This Row],[Vérif]]="D",BalanceN[[#This Row],[BE_Credit]]>0),"A",IF(AND(BalanceN[[#This Row],[Vérif]]="C",BalanceN[[#This Row],[BE_Debit]]>0),"A","")) | N12: 131000 | O12: Résultat net | Q12: 66631518 | R12: 66631518 | V12: =VALUE(LEFT(BalanceN1[[#This Row],[Compte]]&"00000000",5)) -> 13100 | W12: {=IF(BalanceN1[[#This Row],[Compte]]="",0,_xlfn.IFNA(INDEX(Plan_Comptable[[Table de Compte]:[Sens]],MATCH(VALUE(LEFT(BalanceN1[[#This Row],[Table]],4)),VALUE(Plan_Comptable[Table de Compte]),0),2),"A"))} -> 0 | X12: =IF(AND(BalanceN1[[#This Row],[Vérif]]="D",BalanceN1[[#This Row],[BS_Credit]]>0),"A",IF(AND(BalanceN1[[#This Row],[Vérif]]="C",BalanceN1[[#This Row],[BS_Debit]]>0),"A","")) | Y12: =IF(AND(BalanceN1[[#This Row],[Vérif]]="D",BalanceN1[[#This Row],[BE_Credit]]>0),"A",IF(AND(BalanceN1[[#This Row],[Vérif]]="C",BalanceN1[[#This Row],[BE_Debit]]>0),"A",""))
A13: 109000 | B13: Apporteurs, capital souscrit, non appelé | E13: 300000000 | F13: 200000000 | G13: 100000000 | I13: =VALUE(LEFT(BalanceN[[#This Row],[Compte]]&"00000000",5)) -> 10900 | J13: {=IF(BalanceN[[#This Row],[Compte]]="",0,_xlfn.IFNA(INDEX(Plan_Comptable[[Table de Compte]:[Sens]],MATCH(VALUE(LEFT(BalanceN[[#This Row],[Table]],4)),VALUE(Plan_Comptable[Table de Compte]),0),2),"A"))} -> 0 | K13: =IF(AND(BalanceN[[#This Row],[Vérif]]="D",BalanceN[[#This Row],[BS_Credit]]>0),"A",IF(AND(BalanceN[[#This Row],[Vérif]]="C",BalanceN[[#This Row],[BS_Debit]]>0),"A","")) | L13: =IF(AND(BalanceN[[#This Row],[Vérif]]="D",BalanceN[[#This Row],[BE_Credit]]>0),"A",IF(AND(BalanceN[[#This Row],[Vérif]]="C",BalanceN[[#This Row],[BE_Debit]]>0),"A","")) | N13: 165200 | O13: Cau.tionoemeots reçus | Q13: 2200000 | U13: 2200000 | V13: =VALUE(LEFT(BalanceN1[[#This Row],[Compte]]&"00000000",5)) -> 16520 | W13: {=IF(BalanceN1[[#This Row],[Compte]]="",0,_xlfn.IFNA(INDEX(Plan_Comptable[[Table de Compte]:[Sens]],MATCH(VALUE(LEFT(BalanceN1[[#This Row],[Table]],4)),VALUE(Plan_Comptable[Table de Compte]),0),2),"A"))} -> 0 | X13: =IF(AND(BalanceN1[[#This Row],[Vérif]]="D",BalanceN1[[#This Row],[BS_Credit]]>0),"A",IF(AND(BalanceN1[[#This Row],[Vérif]]="C",BalanceN1[[#This Row],[BS_Debit]]>0),"A","")) | Y13: =IF(AND(BalanceN1[[#This Row],[Vérif]]="D",BalanceN1[[#This Row],[BE_Credit]]>0),"A",IF(AND(BalanceN1[[#This Row],[Vérif]]="C",BalanceN1[[#This Row],[BE_Debit]]>0),"A",""))
A14: 111000 | B14: Réserve légale | D14: 20000000 | H14: 20000000 | I14: =VALUE(LEFT(BalanceN[[#This Row],[Compte]]&"00000000",5)) -> 11100 | J14: {=IF(BalanceN[[#This Row],[Compte]]="",0,_xlfn.IFNA(INDEX(Plan_Comptable[[Table de Compte]:[Sens]],MATCH(VALUE(LEFT(BalanceN[[#This Row],[Table]],4)),VALUE(Plan_Comptable[Table de Compte]),0),2),"A"))} -> 0 | K14: =IF(AND(BalanceN[[#This Row],[Vérif]]="D",BalanceN[[#This Row],[BS_Credit]]>0),"A",IF(AND(BalanceN[[#This Row],[Vérif]]="C",BalanceN[[#This Row],[BS_Debit]]>0),"A","")) | L14: =IF(AND(BalanceN[[#This Row],[Vérif]]="D",BalanceN[[#This Row],[BE_Credit]]>0),"A",IF(AND(BalanceN[[#This Row],[Vérif]]="C",BalanceN[[#This Row],[BE_Debit]]>0),"A","")) | N14: 196100 | O14: Provision pour pensions et obligations assimilées | Q14: 47553935 | R14: 3771900 | S14: 11082662 | U14: 54864697 | V14: =VALUE(LEFT(BalanceN1[[#This Row],[Compte]]&"00000000",5)) -> 19610 | W14: {=IF(BalanceN1[[#This Row],[Compte]]="",0,_xlfn.IFNA(INDEX(Plan_Comptable[[Table de Compte]:[Sens]],MATCH(VALUE(LEFT(BalanceN1[[#This Row],[Table]],4)),VALUE(Plan_Comptable[Table de Compte]),0),2),"A"))} -> 0 | X14: =IF(AND(BalanceN1[[#This Row],[Vérif]]="D",BalanceN1[[#This Row],[BS_Credit]]>0),"A",IF(AND(BalanceN1[[#This Row],[Vérif]]="C",BalanceN1[[#This Row],[BS_Debit]]>0),"A","")) | Y14: =IF(AND(BalanceN1[[#This Row],[Vérif]]="D",BalanceN1[[#This Row],[BE_Credit]]>0),"A",IF(AND(BalanceN1[[#This Row],[Vérif]]="C",BalanceN1[[#This Row],[BE_Debit]]>0),"A",""))
A15: 121 | B15: Report à nouveau | D15: 47450317 | E15: 90000000 | F15: 118619674 | H15: 76069991 | I15: =VALUE(LEFT(BalanceN[[#This Row],[Compte]]&"00000000",5)) -> 12100 | J15: {=IF(BalanceN[[#This Row],[Compte]]="",0,_xlfn.IFNA(INDEX(Plan_Comptable[[Table de Compte]:[Sens]],MATCH(VALUE(LEFT(BalanceN[[#This Row],[Table]],4)),VALUE(Plan_Comptable[Table de Compte]),0),2),"A"))} -> 0 | K15: =IF(AND(BalanceN[[#This Row],[Vérif]]="D",BalanceN[[#This Row],[BS_Credit]]>0),"A",IF(AND(BalanceN[[#This Row],[Vérif]]="C",BalanceN[[#This Row],[BS_Debit]]>0),"A","")) | L15: =IF(AND(BalanceN[[#This Row],[Vérif]]="D",BalanceN[[#This Row],[BE_Credit]]>0),"A",IF(AND(BalanceN[[#This Row],[Vérif]]="C",BalanceN[[#This Row],[BE_Debit]]>0),"A","")) | N15: 2131 | O15: Logiciels | P15: 1050000 | T15: 1050000 | V15: =VALUE(LEFT(BalanceN1[[#This Row],[Compte]]&"00000000",5)) -> 21310 | W15: {=IF(BalanceN1[[#This Row],[Compte]]="",0,_xlfn.IFNA(INDEX(Plan_Comptable[[Table de Compte]:[Sens]],MATCH(VALUE(LEFT(BalanceN1[[#This Row],[Table]],4)),VALUE(Plan_Comptable[Table de Compte]),0),2),"A"))} -> D | X15: =IF(AND(BalanceN1[[#This Row],[Vérif]]="D",BalanceN1[[#This Row],[BS_Credit]]>0),"A",IF(AND(BalanceN1[[#This Row],[Vérif]]="C",BalanceN1[[#This Row],[BS_Debit]]>0),"A","")) | Y15: =IF(AND(BalanceN1[[#This Row],[Vérif]]="D",BalanceN1[[#This Row],[BE_Credit]]>0),"A",IF(AND(BalanceN1[[#This Row],[Vérif]]="C",BalanceN1[[#This Row],[BE_Debit]]>0),"A",""))
A16: 131000 | B16: Résultat net | D16: 118619674 | E16: 118619674 | I16: =VALUE(LEFT(BalanceN[[#This Row],[Compte]]&"00000000",5)) -> 13100 | J16: {=IF(BalanceN[[#This Row],[Compte]]="",0,_xlfn.IFNA(INDEX(Plan_Comptable[[Table de Compte]:[Sens]],MATCH(VALUE(LEFT(BalanceN[[#This Row],[Table]],4)),VALUE(Plan_Comptable[Table de Compte]),0),2),"A"))} -> 0 | K16: =IF(AND(BalanceN[[#This Row],[Vérif]]="D",BalanceN[[#This Row],[BS_Credit]]>0),"A",IF(AND(BalanceN[[#This Row],[Vérif]]="C",BalanceN[[#This Row],[BS_Debit]]>0),"A","")) | L16: =IF(AND(BalanceN[[#This Row],[Vérif]]="D",BalanceN[[#This Row],[BE_Credit]]>0),"A",IF(AND(BalanceN[[#This Row],[Vérif]]="C",BalanceN[[#This Row],[BE_Debit]]>0),"A","")) | N16: 215000 | O16: Fonds commercial | P16: 1600000 | T16: 1600000 | V16: =VALUE(LEFT(BalanceN1[[#This Row],[Compte]]&"00000000",5)) -> 21500 | W16: {=IF(BalanceN1[[#This Row],[Compte]]="",0,_xlfn.IFNA(INDEX(Plan_Comptable[[Table de Compte]:[Sens]],MATCH(VALUE(LEFT(BalanceN1[[#This Row],[Table]],4)),VALUE(Plan_Comptable[Table de Compte]),0),2),"A"))} -> D | X16: =IF(AND(BalanceN1[[#This Row],[Vérif]]="D",BalanceN1[[#This Row],[BS_Credit]]>0),"A",IF(AND(BalanceN1[[#This Row],[Vérif]]="C",BalanceN1[[#This Row],[BS_Debit]]>0),"A","")) | Y16: =IF(AND(BalanceN1[[#This Row],[Vérif]]="D",BalanceN1[[#This Row],[BE_Credit]]>0),"A",IF(AND(BalanceN1[[#This Row],[Vérif]]="C",BalanceN1[[#This Row],[BE_Debit]]>0),"A",""))
A17: 141600 | B17: Subvention d'investissement | F17: 2000000 | H17: 2000000 | I17: =VALUE(LEFT(BalanceN[[#This Row],[Compte]]&"00000000",5)) -> 14160 | J17: {=IF(BalanceN[[#This Row],[Compte]]="",0,_xlfn.IFNA(INDEX(Plan_Comptable[[Table de Compte]:[Sens]],MATCH(VALUE(LEFT(BalanceN[[#This Row],[Table]],4)),VALUE(Plan_Comptable[Table de Compte]),0),2),"A"))} -> 0 | K17: =IF(AND(BalanceN[[#This Row],[Vérif]]="D",BalanceN[[#This Row],[BS_Credit]]>0),"A",IF(AND(BalanceN[[#This Row],[Vérif]]="C",BalanceN[[#This Row],[BS_Debit]]>0),"A","")) | L17: =IF(AND(BalanceN[[#This Row],[Vérif]]="D",BalanceN[[#This Row],[BE_Credit]]>0),"A",IF(AND(BalanceN[[#This Row],[Vérif]]="C",BalanceN[[#This Row],[BE_Debit]]>0),"A","")) | N17: 2231 | O17: Terrains bâtis | P17: 12500000 | T17: 12500000 | V17: =VALUE(LEFT(BalanceN1[[#This Row],[Compte]]&"00000000",5)) -> 22310 | W17: {=IF(BalanceN1[[#This Row],[Compte]]="",0,_xlfn.IFNA(INDEX(Plan_Comptable[[Table de Compte]:[Sens]],MATCH(VALUE(LEFT(BalanceN1[[#This Row],[Table]],4)),VALUE(Plan_Comptable[Table de Compte]),0),2),"A"))} -> D | X17: =IF(AND(BalanceN1[[#This Row],[Vérif]]="D",BalanceN1[[#This Row],[BS_Credit]]>0),"A",IF(AND(BalanceN1[[#This Row],[Vérif]]="C",BalanceN1[[#This Row],[BS_Debit]]>0),"A","")) | Y17: =IF(AND(BalanceN1[[#This Row],[Vérif]]="D",BalanceN1[[#This Row],[BE_Credit]]>0),"A",IF(AND(BalanceN1[[#This Row],[Vérif]]="C",BalanceN1[[#This Row],[BE_Debit]]>0),"A",""))
A18: 154000 | B18: Provisions spéciales de réévaluation | F18: 40000000 | H18: 40000000 | I18: =VALUE(LEFT(BalanceN[[#This Row],[Compte]]&"00000000",5)) -> 15400 | J18: {=IF(BalanceN[[#This Row],[Compte]]="",0,_xlfn.IFNA(INDEX(Plan_Comptable[[Table de Compte]:[Sens]],MATCH(VALUE(LEFT(BalanceN[[#This Row],[Table]],4)),VALUE(Plan_Comptable[Table de Compte]),0),2),"A"))} -> 0 | K18: =IF(AND(BalanceN[[#This Row],[Vérif]]="D",BalanceN[[#This Row],[BS_Credit]]>0),"A",IF(AND(BalanceN[[#This Row],[Vérif]]="C",BalanceN[[#This Row],[BS_Debit]]>0),"A","")) | L18: =IF(AND(BalanceN[[#This Row],[Vérif]]="D",BalanceN[[#This Row],[BE_Credit]]>0),"A",IF(AND(BalanceN[[#This Row],[Vérif]]="C",BalanceN[[#This Row],[BE_Debit]]>0),"A","")) | N18: 2298 | O18: Aménagement de terraio en cours | P18: 22673950 | T18: 22673950 | V18: =VALUE(LEFT(BalanceN1[[#This Row],[Compte]]&"00000000",5)) -> 22980 | W18: {=IF(BalanceN1[[#This Row],[Compte]]="",0,_xlfn.IFNA(INDEX(Plan_Comptable[[Table de Compte]:[Sens]],MATCH(VALUE(LEFT(BalanceN1[[#This Row],[Table]],4)),VALUE(Plan_Comptable[Table de Compte]),0),2),"A"))} -> D | X18: =IF(AND(BalanceN1[[#This Row],[Vérif]]="D",BalanceN1[[#This Row],[BS_Credit]]>0),"A",IF(AND(BalanceN1[[#This Row],[Vérif]]="C",BalanceN1[[#This Row],[BS_Debit]]>0),"A","")) | Y18: =IF(AND(BalanceN1[[#This Row],[Vérif]]="D",BalanceN1[[#This Row],[BE_Credit]]>0),"A",IF(AND(BalanceN1[[#This Row],[Vérif]]="C",BalanceN1[[#This Row],[BE_Debit]]>0),"A",""))
A19: 162000 | B19: Emprunt bancaire | E19: 7500925 | F19: 100000000 | H19: 92499075 | I19: =VALUE(LEFT(BalanceN[[#This Row],[Compte]]&"00000000",5)) -> 16200 | J19: {=IF(BalanceN[[#This Row],[Compte]]="",0,_xlfn.IFNA(INDEX(Plan_Comptable[[Table de Compte]:[Sens]],MATCH(VALUE(LEFT(BalanceN[[#This Row],[Table]],4)),VALUE(Plan_Comptable[Table de Compte]),0),2),"A"))} -> 0 | K19: =IF(AND(BalanceN[[#This Row],[Vérif]]="D",BalanceN[[#This Row],[BS_Credit]]>0),"A",IF(AND(BalanceN[[#This Row],[Vérif]]="C",BalanceN[[#This Row],[BS_Debit]]>0),"A","")) | L19: =IF(AND(BalanceN[[#This Row],[Vérif]]="D",BalanceN[[#This Row],[BE_Credit]]>0),"A",IF(AND(BalanceN[[#This Row],[Vérif]]="C",BalanceN[[#This Row],[BE_Debit]]>0),"A","")) | N19: 231100 | O19: Bâtiments industriels sur sol propre | P19: 55000000 | T19: 55000000 | V19: =VALUE(LEFT(BalanceN1[[#This Row],[Compte]]&"00000000",5)) -> 23110 | W19: {=IF(BalanceN1[[#This Row],[Compte]]="",0,_xlfn.IFNA(INDEX(Plan_Comptable[[Table de Compte]:[Sens]],MATCH(VALUE(LEFT(BalanceN1[[#This Row],[Table]],4)),VALUE(Plan_Comptable[Table de Compte]),0),2),"A"))} -> D | X19: =IF(AND(BalanceN1[[#This Row],[Vérif]]="D",BalanceN1[[#This Row],[BS_Credit]]>0),"A",IF(AND(BalanceN1[[#This Row],[Vérif]]="C",BalanceN1[[#This Row],[BS_Debit]]>0),"A","")) | Y19: =IF(AND(BalanceN1[[#This Row],[Vérif]]="D",BalanceN1[[#This Row],[BE_Credit]]>0),"A",IF(AND(BalanceN1[[#This Row],[Vérif]]="C",BalanceN1[[#This Row],[BE_Debit]]>0),"A",""))
A20: 165200 | B20: Cautionnements reçus | D20: 2200000 | H20: 2200000 | I20: =VALUE(LEFT(BalanceN[[#This Row],[Compte]]&"00000000",5)) -> 16520 | J20: {=IF(BalanceN[[#This Row],[Compte]]="",0,_xlfn.IFNA(INDEX(Plan_Comptable[[Table de Compte]:[Sens]],MATCH(VALUE(LEFT(BalanceN[[#This Row],[Table]],4)),VALUE(Plan_Comptable[Table de Compte]),0),2),"A"))} -> 0 | K20: =IF(AND(BalanceN[[#This Row],[Vérif]]="D",BalanceN[[#This Row],[BS_Credit]]>0),"A",IF(AND(BalanceN[[#This Row],[Vérif]]="C",BalanceN[[#This Row],[BS_Debit]]>0),"A","")) | L20: =IF(AND(BalanceN[[#This Row],[Vérif]]="D",BalanceN[[#This Row],[BE_Credit]]>0),"A",IF(AND(BalanceN[[#This Row],[Vérif]]="C",BalanceN[[#This Row],[BE_Debit]]>0),"A","")) | N20: 232100 | O20: Bâtiments industriels sur sol d'autrui | P20: 231411100 | T20: 231411100 | V20: =VALUE(LEFT(BalanceN1[[#This Row],[Compte]]&"00000000",5)) -> 23210 | W20: {=IF(BalanceN1[[#This Row],[Compte]]="",0,_xlfn.IFNA(INDEX(Plan_Comptable[[Table de Compte]:[Sens]],MATCH(VALUE(LEFT(BalanceN1[[#This Row],[Table]],4)),VALUE(Plan_Comptable[Table de Compte]),0),2),"A"))} -> D | X20: =IF(AND(BalanceN1[[#This Row],[Vérif]]="D",BalanceN1[[#This Row],[BS_Credit]]>0),"A",IF(AND(BalanceN1[[#This Row],[Vérif]]="C",BalanceN1[[#This Row],[BS_Debit]]>0),"A","")) | Y20: =IF(AND(BalanceN1[[#This Row],[Vérif]]="D",BalanceN1[[#This Row],[BE_Credit]]>0),"A",IF(AND(BalanceN1[[#This Row],[Vérif]]="C",BalanceN1[[#This Row],[BE_Debit]]>0),"A",""))
A21: 196100 | B21: Provisions pour pensions et obligations similaires | D21: 54864697 | E21: 6701530 | F21: 13953199 | H21: 62116366 | I21: =VALUE(LEFT(BalanceN[[#This Row],[Compte]]&"00000000",5)) -> 19610 | J21: {=IF(BalanceN[[#This Row],[Compte]]="",0,_xlfn.IFNA(INDEX(Plan_Comptable[[Table de Compte]:[Sens]],MATCH(VALUE(LEFT(BalanceN[[#This Row],[Table]],4)),VALUE(Plan_Comptable[Table de Compte]),0),2),"A"))} -> 0 | K21: =IF(AND(BalanceN[[#This Row],[Vérif]]="D",BalanceN[[#This Row],[BS_Credit]]>0),"A",IF(AND(BalanceN[[#This Row],[Vérif]]="C",BalanceN[[#This Row],[BS_Debit]]>0),"A","")) | L21: =IF(AND(BalanceN[[#This Row],[Vérif]]="D",BalanceN[[#This Row],[BE_Credit]]>0),"A",IF(AND(BalanceN[[#This Row],[Vérif]]="C",BalanceN[[#This Row],[BE_Debit]]>0),"A","")) | N21: 235100 | O21: Installatioos générales | P21: 60263648 | T21: 60263648 | V21: =VALUE(LEFT(BalanceN1[[#This Row],[Compte]]&"00000000",5)) -> 23510 | W21: {=IF(BalanceN1[[#This Row],[Compte]]="",0,_xlfn.IFNA(INDEX(Plan_Comptable[[Table de Compte]:[Sens]],MATCH(VALUE(LEFT(BalanceN1[[#This Row],[Table]],4)),VALUE(Plan_Comptable[Table de Compte]),0),2),"A"))} -> D | X21: =IF(AND(BalanceN1[[#This Row],[Vérif]]="D",BalanceN1[[#This Row],[BS_Credit]]>0),"A",IF(AND(BalanceN1[[#This Row],[Vérif]]="C",BalanceN1[[#This Row],[BS_Debit]]>0),"A","")) | Y21: =IF(AND(BalanceN1[[#This Row],[Vérif]]="D",BalanceN1[[#This Row],[BE_Credit]]>0),"A",IF(AND(BalanceN1[[#This Row],[Vérif]]="C",BalanceN1[[#This Row],[BE_Debit]]>0),"A",""))
A22: 2131 | B22: Logiciels | C22: 1050000 | E22: 2000000 | G22: 3050000 | I22: =VALUE(LEFT(BalanceN[[#This Row],[Compte]]&"00000000",5)) -> 21310 | J22: {=IF(BalanceN[[#This Row],[Compte]]="",0,_xlfn.IFNA(INDEX(Plan_Comptable[[Table de Compte]:[Sens]],MATCH(VALUE(LEFT(BalanceN[[#This Row],[Table]],4)),VALUE(Plan_Comptable[Table de Compte]),0),2),"A"))} -> D | K22: =IF(AND(BalanceN[[#This Row],[Vérif]]="D",BalanceN[[#This Row],[BS_Credit]]>0),"A",IF(AND(BalanceN[[#This Row],[Vérif]]="C",BalanceN[[#This Row],[BS_Debit]]>0),"A","")) | L22: =IF(AND(BalanceN[[#This Row],[Vérif]]="D",BalanceN[[#This Row],[BE_Credit]]>0),"A",IF(AND(BalanceN[[#This Row],[Vérif]]="C",BalanceN[[#This Row],[BE_Debit]]>0),"A","")) | N22: 238000 | O22: Autres installations et agencements | P22: 11064619 | T22: 11064619 | V22: =VALUE(LEFT(BalanceN1[[#This Row],[Compte]]&"00000000",5)) -> 23800 | W22: {=IF(BalanceN1[[#This Row],[Compte]]="",0,_xlfn.IFNA(INDEX(Plan_Comptable[[Table de Compte]:[Sens]],MATCH(VALUE(LEFT(BalanceN1[[#This Row],[Table]],4)),VALUE(Plan_Comptable[Table de Compte]),0),2),"A"))} -> D | X22: =IF(AND(BalanceN1[[#This Row],[Vérif]]="D",BalanceN1[[#This Row],[BS_Credit]]>0),"A",IF(AND(BalanceN1[[#This Row],[Vérif]]="C",BalanceN1[[#This Row],[BS_Debit]]>0),"A","")) | Y22: =IF(AND(BalanceN1[[#This Row],[Vérif]]="D",BalanceN1[[#This Row],[BE_Credit]]>0),"A",IF(AND(BalanceN1[[#This Row],[Vérif]]="C",BalanceN1[[#This Row],[BE_Debit]]>0),"A",""))
A23: 215000 | B23: Fonds commercial | C23: 1600000 | G23: 1600000 | I23: =VALUE(LEFT(BalanceN[[#This Row],[Compte]]&"00000000",5)) -> 21500 | J23: {=IF(BalanceN[[#This Row],[Compte]]="",0,_xlfn.IFNA(INDEX(Plan_Comptable[[Table de Compte]:[Sens]],MATCH(VALUE(LEFT(BalanceN[[#This Row],[Table]],4)),VALUE(Plan_Comptable[Table de Compte]),0),2),"A"))} -> D | K23: =IF(AND(BalanceN[[#This Row],[Vérif]]="D",BalanceN[[#This Row],[BS_Credit]]>0),"A",IF(AND(BalanceN[[#This Row],[Vérif]]="C",BalanceN[[#This Row],[BS_Debit]]>0),"A","")) | L23: =IF(AND(BalanceN[[#This Row],[Vérif]]="D",BalanceN[[#This Row],[BE_Credit]]>0),"A",IF(AND(BalanceN[[#This Row],[Vérif]]="C",BalanceN[[#This Row],[BE_Debit]]>0),"A","")) | N23: 241100 | O23: Matériel industriel | P23: 74507291 | R23: 17153112 | S23: 350000 | T23: 91310403 | V23: =VALUE(LEFT(BalanceN1[[#This Row],[Compte]]&"00000000",5)) -> 24110 | W23: {=IF(BalanceN1[[#This Row],[Compte]]="",0,_xlfn.IFNA(INDEX(Plan_Comptable[[Table de Compte]:[Sens]],MATCH(VALUE(LEFT(BalanceN1[[#This Row],[Table]],4)),VALUE(Plan_Comptable[Table de Compte]),0),2),"A"))} -> D | X23: =IF(AND(BalanceN1[[#This Row],[Vérif]]="D",BalanceN1[[#This Row],[BS_Credit]]>0),"A",IF(AND(BalanceN1[[#This Row],[Vérif]]="C",BalanceN1[[#This Row],[BS_Debit]]>0),"A","")) | Y23: =IF(AND(BalanceN1[[#This Row],[Vérif]]="D",BalanceN1[[#This Row],[BE_Credit]]>0),"A",IF(AND(BalanceN1[[#This Row],[Vérif]]="C",BalanceN1[[#This Row],[BE_Debit]]>0),"A",""))
A24: 2231 | B24: Terrains bâtis | C24: 12500000 | E24: 3500000 | G24: 16000000 | I24: =VALUE(LEFT(BalanceN[[#This Row],[Compte]]&"00000000",5)) -> 22310 | J24: {=IF(BalanceN[[#This Row],[Compte]]="",0,_xlfn.IFNA(INDEX(Plan_Comptable[[Table de Compte]:[Sens]],MATCH(VALUE(LEFT(BalanceN[[#This Row],[Table]],4)),VALUE(Plan_Comptable[Table de Compte]),0),2),"A"))} -> D | K24: =IF(AND(BalanceN[[#This Row],[Vérif]]="D",BalanceN[[#This Row],[BS_Credit]]>0),"A",IF(AND(BalanceN[[#This Row],[Vérif]]="C",BalanceN[[#This Row],[BS_Debit]]>0),"A","")) | L24: =IF(AND(BalanceN[[#This Row],[Vérif]]="D",BalanceN[[#This Row],[BE_Credit]]>0),"A",IF(AND(BalanceN[[#This Row],[Vérif]]="C",BalanceN[[#This Row],[BE_Debit]]>0),"A","")) | N24: 244100 | O24: Matériel de bureau | P24: 1325000 | T24: 1325000 | V24: =VALUE(LEFT(BalanceN1[[#This Row],[Compte]]&"00000000",5)) -> 24410 | W24: {=IF(BalanceN1[[#This Row],[Compte]]="",0,_xlfn.IFNA(INDEX(Plan_Comptable[[Table de Compte]:[Sens]],MATCH(VALUE(LEFT(BalanceN1[[#This Row],[Table]],4)),VALUE(Plan_Comptable[Table de Compte]),0),2),"A"))} -> D | X24: =IF(AND(BalanceN1[[#This Row],[Vérif]]="D",BalanceN1[[#This Row],[BS_Credit]]>0),"A",IF(AND(BalanceN1[[#This Row],[Vérif]]="C",BalanceN1[[#This Row],[BS_Debit]]>0),"A","")) | Y24: =IF(AND(BalanceN1[[#This Row],[Vérif]]="D",BalanceN1[[#This Row],[BE_Credit]]>0),"A",IF(AND(BalanceN1[[#This Row],[Vérif]]="C",BalanceN1[[#This Row],[BE_Debit]]>0),"A",""))
A25: 2298 | B25: Aménagement de terrain en cours | C25: 22673950 | G25: 22673950 | I25: =VALUE(LEFT(BalanceN[[#This Row],[Compte]]&"00000000",5)) -> 22980 | J25: {=IF(BalanceN[[#This Row],[Compte]]="",0,_xlfn.IFNA(INDEX(Plan_Comptable[[Table de Compte]:[Sens]],MATCH(VALUE(LEFT(BalanceN[[#This Row],[Table]],4)),VALUE(Plan_Comptable[Table de Compte]),0),2),"A"))} -> D | K25: =IF(AND(BalanceN[[#This Row],[Vérif]]="D",BalanceN[[#This Row],[BS_Credit]]>0),"A",IF(AND(BalanceN[[#This Row],[Vérif]]="C",BalanceN[[#This Row],[BS_Debit]]>0),"A","")) | L25: =IF(AND(BalanceN[[#This Row],[Vérif]]="D",BalanceN[[#This Row],[BE_Credit]]>0),"A",IF(AND(BalanceN[[#This Row],[Vérif]]="C",BalanceN[[#This Row],[BE_Debit]]>0),"A","")) | N25: 244200 | O25: Matériel infonnatique | P25: 6867703 | T25: 6867703 | V25: =VALUE(LEFT(BalanceN1[[#This Row],[Compte]]&"00000000",5)) -> 24420 | W25: {=IF(BalanceN1[[#This Row],[Compte]]="",0,_xlfn.IFNA(INDEX(Plan_Comptable[[Table de Compte]:[Sens]],MATCH(VALUE(LEFT(BalanceN1[[#This Row],[Table]],4)),VALUE(Plan_Comptable[Table de Compte]),0),2),"A"))} -> D | X25: =IF(AND(BalanceN1[[#This Row],[Vérif]]="D",BalanceN1[[#This Row],[BS_Credit]]>0),"A",IF(AND(BalanceN1[[#This Row],[Vérif]]="C",BalanceN1[[#This Row],[BS_Debit]]>0),"A","")) | Y25: =IF(AND(BalanceN1[[#This Row],[Vérif]]="D",BalanceN1[[#This Row],[BE_Credit]]>0),"A",IF(AND(BalanceN1[[#This Row],[Vérif]]="C",BalanceN1[[#This Row],[BE_Debit]]>0),"A",""))
A26: 231100 | B26: Bâtiments industriels sur sol propre | C26: 55000000 | E26: 23000000 | G26: 78000000 | I26: =VALUE(LEFT(BalanceN[[#This Row],[Compte]]&"00000000",5)) -> 23110 | J26: {=IF(BalanceN[[#This Row],[Compte]]="",0,_xlfn.IFNA(INDEX(Plan_Comptable[[Table de Compte]:[Sens]],MATCH(VALUE(LEFT(BalanceN[[#This Row],[Table]],4)),VALUE(Plan_Comptable[Table de Compte]),0),2),"A"))} -> D | K26: =IF(AND(BalanceN[[#This Row],[Vérif]]="D",BalanceN[[#This Row],[BS_Credit]]>0),"A",IF(AND(BalanceN[[#This Row],[Vérif]]="C",BalanceN[[#This Row],[BS_Debit]]>0),"A","")) | L26: =IF(AND(BalanceN[[#This Row],[Vérif]]="D",BalanceN[[#This Row],[BE_Credit]]>0),"A",IF(AND(BalanceN[[#This Row],[Vérif]]="C",BalanceN[[#This Row],[BE_Debit]]>0),"A","")) | N26: 244400 | O26: Mobilier de bureau | P26: 4968900 | T26: 4968900 | V26: =VALUE(LEFT(BalanceN1[[#This Row],[Compte]]&"00000000",5)) -> 24440 | W26: {=IF(BalanceN1[[#This Row],[Compte]]="",0,_xlfn.IFNA(INDEX(Plan_Comptable[[Table de Compte]:[Sens]],MATCH(VALUE(LEFT(BalanceN1[[#This Row],[Table]],4)),VALUE(Plan_Comptable[Table de Compte]),0),2),"A"))} -> D | X26: =IF(AND(BalanceN1[[#This Row],[Vérif]]="D",BalanceN1[[#This Row],[BS_Credit]]>0),"A",IF(AND(BalanceN1[[#This Row],[Vérif]]="C",BalanceN1[[#This Row],[BS_Debit]]>0),"A","")) | Y26: =IF(AND(BalanceN1[[#This Row],[Vérif]]="D",BalanceN1[[#This Row],[BE_Credit]]>0),"A",IF(AND(BalanceN1[[#This Row],[Vérif]]="C",BalanceN1[[#This Row],[BE_Debit]]>0),"A",""))
A27: 232100 | B27: Bâtiments industriels sur sol d'autrui | C27: 231411100 | E27: 432000000 | G27: 663411100 | I27: =VALUE(LEFT(BalanceN[[#This Row],[Compte]]&"00000000",5)) -> 23210 | J27: {=IF(BalanceN[[#This Row],[Compte]]="",0,_xlfn.IFNA(INDEX(Plan_Comptable[[Table de Compte]:[Sens]],MATCH(VALUE(LEFT(BalanceN[[#This Row],[Table]],4)),VALUE(Plan_Comptable[Table de Compte]),0),2),"A"))} -> D | K27: =IF(AND(BalanceN[[#This Row],[Vérif]]="D",BalanceN[[#This Row],[BS_Credit]]>0),"A",IF(AND(BalanceN[[#This Row],[Vérif]]="C",BalanceN[[#This Row],[BS_Debit]]>0),"A","")) | L27: =IF(AND(BalanceN[[#This Row],[Vérif]]="D",BalanceN[[#This Row],[BE_Credit]]>0),"A",IF(AND(BalanceN[[#This Row],[Vérif]]="C",BalanceN[[#This Row],[BE_Debit]]>0),"A","")) | N27: 245100 | O27: Matériel automobile | P27: 54050000 | T27: 54050000 | V27: =VALUE(LEFT(BalanceN1[[#This Row],[Compte]]&"00000000",5)) -> 24510 | W27: {=IF(BalanceN1[[#This Row],[Compte]]="",0,_xlfn.IFNA(INDEX(Plan_Comptable[[Table de Compte]:[Sens]],MATCH(VALUE(LEFT(BalanceN1[[#This Row],[Table]],4)),VALUE(Plan_Comptable[Table de Compte]),0),2),"A"))} -> D | X27: =IF(AND(BalanceN1[[#This Row],[Vérif]]="D",BalanceN1[[#This Row],[BS_Credit]]>0),"A",IF(AND(BalanceN1[[#This Row],[Vérif]]="C",BalanceN1[[#This Row],[BS_Debit]]>0),"A","")) | Y27: =IF(AND(BalanceN1[[#This Row],[Vérif]]="D",BalanceN1[[#This Row],[BE_Credit]]>0),"A",IF(AND(BalanceN1[[#This Row],[Vérif]]="C",BalanceN1[[#This Row],[BE_Debit]]>0),"A",""))
A28: 235100 | B28: Installations générales | C28: 60263648 | E28: 1000000 | G28: 61263648 | I28: =VALUE(LEFT(BalanceN[[#This Row],[Compte]]&"00000000",5)) -> 23510 | J28: {=IF(BalanceN[[#This Row],[Compte]]="",0,_xlfn.IFNA(INDEX(Plan_Comptable[[Table de Compte]:[Sens]],MATCH(VALUE(LEFT(BalanceN[[#This Row],[Table]],4)),VALUE(Plan_Comptable[Table de Compte]),0),2),"A"))} -> D | K28: =IF(AND(BalanceN[[#This Row],[Vérif]]="D",BalanceN[[#This Row],[BS_Credit]]>0),"A",IF(AND(BalanceN[[#This Row],[Vérif]]="C",BalanceN[[#This Row],[BS_Debit]]>0),"A","")) | L28: =IF(AND(BalanceN[[#This Row],[Vérif]]="D",BalanceN[[#This Row],[BE_Credit]]>0),"A",IF(AND(BalanceN[[#This Row],[Vérif]]="C",BalanceN[[#This Row],[BE_Debit]]>0),"A","")) | N28: 272800 | O28: Autres prêts au personnel | P28: 1245000 | R28: 682000 | T28: 1927000 | V28: =VALUE(LEFT(BalanceN1[[#This Row],[Compte]]&"00000000",5)) -> 27280 | W28: {=IF(BalanceN1[[#This Row],[Compte]]="",0,_xlfn.IFNA(INDEX(Plan_Comptable[[Table de Compte]:[Sens]],MATCH(VALUE(LEFT(BalanceN1[[#This Row],[Table]],4)),VALUE(Plan_Comptable[Table de Compte]),0),2),"A"))} -> D | X28: =IF(AND(BalanceN1[[#This Row],[Vérif]]="D",BalanceN1[[#This Row],[BS_Credit]]>0),"A",IF(AND(BalanceN1[[#This Row],[Vérif]]="C",BalanceN1[[#This Row],[BS_Debit]]>0),"A","")) | Y28: =IF(AND(BalanceN1[[#This Row],[Vérif]]="D",BalanceN1[[#This Row],[BE_Credit]]>0),"A",IF(AND(BalanceN1[[#This Row],[Vérif]]="C",BalanceN1[[#This Row],[BE_Debit]]>0),"A",""))
